Workbook

Sheet Test Cases
A1: Case ID | B1: Module | C1: Title | D1: Priority | E1: Type | F1: Preconditions | G1: Test Steps | H1: Expected Result | I1: Actual Result | J1: Status | K1: Notes
A2: TC-ONB-001 | B2: Onboarding | C2: Opening animation completes and reveals the kitchen | D2: High | E2: UI | F2: Fresh install or app relaunch; network available. | G2: 1. Launch the app. 2. Wait for the opening sequence. 3. Observe the home kitchen. | H2: The opener finishes, the 3D kitchen appears, and the app is interactive. It does not stay on the opener forever. | I2: The opener finishes, the 3D kitchen appears, and the app is interactive. | J2: Pass
A3: TC-ONB-002 | B3: Onboarding | C3: First-use journey is shown only once | D3: High | E3: Functional | F3: Device has no completed first-use flag. | G3: 1. Launch after a fresh install. 2. Complete the first-use pages and enter the kitchen. 3. Force-close and reopen the app. | H3: The journey appears on first launch. After completion it does not appear again on the same device. | I3: The journey only appears on first launch. | J3: Pass
A4: TC-ONB-003 | B4: Onboarding | C4: First-use pages can be navigated forward and back | D4: Medium | E4: UI | F4: First-use journey is visible. | G4: 1. Open the journey. 2. Use Next through each page. 3. Use Back to return to an earlier page. | H4: Progress text updates. Back restores the previous page. Enter kitchen completes the flow. | I4: Smoothly back to the previous pages. | J4: Pass
A5: TC-ONB-004 | B5: Onboarding | C5: Device bootstrap creates a personal fridge | D5: High | E5: Integration | F5: New device ID; Express and Supabase reachable. | G5: 1. Complete first launch. 2. Open Fridge. 3. Confirm the fridge name/scope. | H5: The device receives a personal fridge with default categories. Inventory can load without a no-fridge error. | I5: The inventory load successfully. | J5: Pass
A6: TC-HOME-001 | B6: Home | C6: Bottom tabs expose Home, Cart, Fridge, and Me | D6: High | E6: UI | F6: First-use journey completed. | G6: 1. Look at the floating tab bar. 2. Tap each visible tab. | H6: Home, Cart, Fridge, and Me (profile) are shown. | I6: All features implemented are shown. | J6: Pass
A7: TC-HOME-002 | B7: Home | C7: 3D fridge hotspot opens the unfiltered fridge | D7: High | E7: Functional | F7: Home kitchen is loaded; inventory may contain expiring items. | G7: 1. Tap the white hotspot on the 3D fridge. 2. Check the fridge filter chips. | H7: The fridge page opens. No filter chip is pre-selected. All active items are listed. | I7: Jump to My Fridge Page. No filter chip is pre-selected. | J7: Pass
A8: TC-HOME-003 | B8: Home | C8: 3D cart hotspot opens shopping | D8: High | E8: Functional | F8: Home kitchen is loaded. | G8: 1. Tap the shopping cart in the 3D scene. | H8: The shopping screen opens after the cinematic transition. | I8: Click the 3D model cart, jump into the Cart screen. | J8: Pass
A9: TC-HOME-004 | B9: Home | C9: 3D mailbox opens the notification inbox | D9: High | E9: Functional | F9: Home kitchen is loaded. | G9: 1. Tap the mailbox in the 3D scene. | H9: The notification inbox opens. Unread count matches the home mailbox badge. | I9: All unexpired messages are shown. | J9: Pass
A10: TC-HOME-005 | B10: Home | C10: Stove and recipe book stay in-scene | D10: Medium | E10: UI | F10: Home kitchen is loaded. | G10: 1. Tap the stove. 2. Tap the recipe book. | H10: Camera/scene feedback occurs in place. The app does not navigate to a recipe destination. | I10: Recommend recipe was not implemented. Nothing would show on the screen. | J10: Pass
A11: TC-HOME-006 | B11: Home | C11: Expiring headline count matches fridge Expiring chip | D11: High | E11: Functional | F11: Fridge contains N active items that expire within 3 days and are not yet expired. | G11: 1. Note the home headline count. 2. Open Fridge from the tab bar. 3. Compare the Expiring chip count. | H11: Home count equals the fridge Expiring chip count. It is not a hardcoded sample such as 2. | I11: The count shown in the Home Screen is same as the expiring chip count. | J11: Pass
A12: TC-HOME-007 | B12: Home | C12: Tapping the expiring headline opens fridge Expiring filter | D12: High | E12: Functional | F12: At least one expiring item exists. | G12: 1. Tap the home headline (e.g. '3 ingredients to use soon'). 2. Inspect fridge chips and list. | H12: Fridge opens with the Expiring chip selected. The list shows only not-expired items with days left <= 3. | I12: Expiring items shown are the left days <= 3. | J12: Pass
A13: TC-HOME-008 | B13: Home | C13: Use first appears when nothing is expiring | D13: High | E13: Functional | F13: Fridge has no expiring items (empty fridge, or all items expire after 3 days / already expired). | G13: 1. Open Home. 2. Read the freshness headline. 3. Tap Use first. | H13: Headline shows Use first in a larger type size. Tap still opens fridge with the Expiring chip selected (empty list is allowed). | I13: Click Use First, jump into expiring chip selected. | J13: Pass
... A37: TC-INV-004 | B37: Inventory entry | C37: AI generate is rate-limited per device | D37: Medium | E37: Negative | F37: Server generation limit is 5 new foods per device per hour. | G37: 1. Trigger AI generate more than 5 times in one hour. | H37: Further generate requests are rejected with a clear error. Manual entry still works. | I37: Exceed the requests limit, the manual entry still work. | J37: Pass
A38: TC-INV-005 | B38: Inventory entry | C38: Expiry cannot be earlier than stocked time | D38: Medium | E38: Negative | F38: Manual form is open. | G38: 1. Set expiry before the recorded stocked date/time. 2. Attempt save. | H38: Save is rejected or blocked. No invalid batch is created. | I38: Input the epxire date is same as stock date, save is rejected. | J38: Pass | K38: The expire date can not be setted before stock date.
A39: TC-INV-006 | B39: Inventory entry | C39: Quantity must be greater than zero | D39: Medium | E39: Negative | F39: Manual form is open. | G39: 1. Set quantity to 0 or a negative number. 2. Attempt save. | H39: Save is rejected. Remaining quantity stays within 0 to initial quantity after create. | I39: The quantity has to be setted. | J39: Pass
A40: TC-INV-007 | B40: Inventory entry | C40: Optional restock rule is saved with the batch | D40: Medium | E40: Functional | F40: Form supports restock thresholds. | G40: 1. Enable restock, set minimum and a higher target. 2. Save. 3. Open the item and Restock chip. | H40: Rule persists. When remaining quantity is at or below minimum, the item appears under Restock. | I40: When the quantity is at or below the min value, the item will show in the restock. | J40: Pass
A41: TC-INV-008 | B41: Inventory entry | C41: Form error from the API is visible | D41: Medium | E41: Negative | F41: Express is running; force a validation failure if possible. | G41: 1. Submit invalid data. 2. Read the form error. | H41: A real error message is shown. The form does not fail silently. | I41: Form will not fail. | J41: Pass | K41: Invalid input is forbidden.
A42: TC-REC-001 | B42: Photo recognition | C42: Supported produce is recognised and prefilled | D42: High | E42: Functional | F42: Camera/gallery available; photo of tomato, banana, or another supported food. | G42: 1. Capture or pick a photo. 2. Confirm the review screen. 3. Continue to the entry form without saving yet. | H42: Name is prefilled from recognition. Freshness maps shelf life: fresh = full preset days, semi_fresh = ceil(40%), rotten = shortest check window. Nothing is written until Save. | I42: Food Recognition works. | J42: Pass
A43: TC-REC-002 | B43: Photo recognition | C43: Unsupported or failed recognition falls back to manual entry | D43: High | E43: Negative | F43: Photo of an unsupported object, or API timeout. | G43: 1. Submit the photo. 2. Observe the result. | H43: User can retake or continue to a blank/manual form. The app does not crash. Image is not stored in Supabase. | I43: Return unsupported item prompt. | J43: Pass
A44: TC-REC-003 | B44: Photo recognition | C44: User can edit prefilled values before save | D44: High | E44: Functional | F44: Recognition returned a draft. | G44: 1. Change name, quantity, or expiry. 2. Save. | H44: Saved batch uses the edited values, not the raw model output. | I44: Edit the value, and saved. | J44: Pass
A45: TC-REC-004 | B45: Photo recognition | C45: Oversized image is rejected | D45: Low | E45: Negative | F45: Image larger than 10 MB if testable. | G45: 1. Select an oversized file. | H45: Request is rejected with a size/type error. No disk write of the photo occurs on the server. | J45: Blocked
A46: TC-DET-001 | B46: Inventory detail | C46: Quantity can be decreased and increased | D46: High | E46: Functional | F46: An active batch with remaining quantity 3 and initial 3. | G46: 1. Open the item sheet. 2. Decrease to 1. 3. Increase back toward initial. | H46: Quantity updates immediately. Value cannot exceed initial quantity or go below 0. An inventory event is recorded. | I46: The quantity can not be increased over initial value or decreased below 0. | J46: Pass
A47: TC-DET-002 | B47: Inventory detail | C47: Quantity 0 marks the batch consumed | D47: High | E47: Functional | F47: Active batch with remaining > 0. | G47: 1. Set remaining quantity to 0. 2. Return to the list. | H47: Batch lifecycle becomes consumed and it is deleted from the list. | I47: After run out of all the eggs, the egg item deleted from list. | J47: Pass
A48: TC-DET-003 | B48: Inventory detail | C48: Edit details updates name, storage, and expiry | D48: High | E48: Functional | F48: Active batch exists. | G48: 1. Open edit. 2. Change storage zone and expiry. 3. Save. | H48: List card reflects the new storage and freshness. | I48: After editing the item, new freshness and expiry shown in the list. | J48: Pass
A49: TC-DET-004 | B49: Inventory detail | C49: Soft delete archives the batch | D49: High | E49: Functional | F49: Active batch exists. | G49: 1. Delete / archive from the detail sheet. 2. Refresh the fridge list. | H49: Item disappears from active inventory. Remaining quantity is zeroed. History is kept; it is not a hard delete. | I49: The deleted item still store in the backend database. | J49: Pass
A50: TC-DET-005 | B50: Inventory detail | C50: Restock rule can be updated from the sheet | D50: Medium | E50: Functional | F50: Item is open. | G50: 1. Set minimum/target. 2. Save. 3. Lower quantity to the minimum. | H50: needsRestock becomes true and the Restock chip includes the item. | I50: needsRestock becomes true and the Restock chip includes the item. | J50: Pass
A51: TC-SHOP-001 | B51: Shopping | C51: Restock tab lists suggested buys | D51: High | E51: Functional | F51: At least one enabled restock rule with stock at or below minimum. | G51: 1. Open Cart tab. 2. Open the Restock view. | H51: Suggested items match restock rules and current stock. Pull-to-refresh reloads. | I51: Restock item show in the suggested column, press add then add into the cart. | J51: Pass
A52: TC-SHOP-002 | B52: Shopping | C52: Cart tab can add a manual item | D52: High | E52: Functional | F52: Shopping screen is open. | G52: 1. Add an item via the shopping add sheet. 2. Confirm it appears in Cart. | H52: Cart item is created against the current fridge. Quantity is editable. | I52: The cart item is created and quantity is editable. | J52: Pass
A53: TC-SHOP-003 | B53: Shopping | C53: Cart quantity can be changed and deleted | D53: High | E53: Functional | F53: Cart has one item. | G53: 1. Use − / +. 2. Type a quantity. 3. Delete the row. | H53: Quantity updates. Delete removes the item. Shared members see the same cart after sync. | J53: Blocked | K53: This function will be implemented in iteration 2.
A54: TC-SHOP-004 | B54: Shopping | C54: Adding a name that already exists in the fridge warns of a duplicate | D54: High | E54: Functional | F54: Fridge already contains Milk; cart add flow is open. | G54: 1. Add Milk to the cart. 2. Read the duplicate warning. | H54: A possible-duplicate warning is shown using current inventory names. User can still add if they choose. | I54: The duplicate warning is shown eye-catching way. | J54: Pass
A55: TC-SHOP-005 | B55: Shopping | C55: Inventory peek shows what is already at home | D55: Medium | E55: Functional | F55: Fridge has inventory; shopping screen is open. | G55: 1. Open inventory peek. 2. Close it. | H55: Current fridge stock is visible without leaving shopping. Closing returns to cart/restock. | I55: Current fridge stock is visible without leaving shopping. Closing returns to cart/restock. | J55: Pass
A56: TC-SHOP-006 | B56: Shopping | C56: Checkout only includes checked cart items | D56: High | E56: Functional | F56: Cart has two items; only one is checked. | G56: 1. Confirm checkout button count. 2. Open checkout review. | H56: Checkout is offered only when at least one item is checked. Review lists only checked items. Unchecked items stay in the cart and are not stocked. | J56: Blocked | K56: This function will be implemented in iteration 2.
A57: TC-SHOP-007 | B57: Shopping | C57: Shopping add sheet reuses the same method picker | D57: Medium | E57: UI | F57: Shopping add is opened. | G57: 1. Inspect manual vs photo options. | H57: The shared AddItemMethodSheet is used. Layout matches fridge add (no arrows; Recommended on its own top row). | J57: Blocked | K57: This function will be implemented in iteration 2.
A58: TC-SHOP-008 | B58: Shopping | C58: Checked checkout items can be stocked into the fridge | D58: High | E58: Functional | F58: One cart item is checked. | G58: 1. Open checkout. 2. Complete InventoryEntryFlow for that item. 3. Open Fridge. | H58: The stocked item becomes an inventory batch and is removed from the cart. Fridge list updates. | J58: Blocked | K58: This function will be implemented in iteration 2.
A59: TC-SHOP-009 | B59: Shopping | C59: Leaving checkout with unstocked checked items prompts first | D59: High | E59: Functional | F59: Checkout is open with at least one checked item not yet stocked. | G59: 1. Attempt to close checkout. 2. Choose stay, then leave anyway. | H59: A leave prompt appears. Stay keeps the review open. Leave anyway closes it without stocking remaining items. | J59: Blocked | K59: This function will be implemented in iteration 2.
A60: TC-NOT-001 | B60: Notifications | C60: Opening the inbox syncs expiring, expired, and restock events | D60: High | E60: Functional | F60: Fridge has an expiring item, an expired item, and a restock-needed item. | G60: 1. Open the mailbox/inbox. | H60: Notifications are generated from live stock. Types include expiring, expired, and restock. No duplicate rows for the same batch/type (dedupe_key). | I60: Notifcation shown in the mailbox. | J60: Pass
A61: TC-NOT-002 | B61: Notifications | C61: Expiring notification uses the same 3-day window | D61: High | E61: Functional | F61: Item expires in 2 days; another expires in 5 days. | G61: 1. Open inbox. 2. Compare with fridge Expiring. | H61: Only the 2-day item creates an expiring notification. The 5-day item does not. | I61: Only 2-day item show in the notification. | J61: Pass
A62: TC-NOT-003 | B62: Notifications | C62: Mark as read is per device | D62: High | E62: Functional | F62: Two devices in the same shared fridge, or simulate two device IDs. | G62: 1. On device A, mark a notification read. 2. Open inbox on device B. | H62: Device A shows it read. Device B still shows unread. Home badge on each device is independent. | J62: Blocked | K62: This function will be implemented in iteration 2.
A63: TC-NOT-004 | B63: Notifications | C63: Opening a notification marks it read and updates counts | D63: High | E63: Functional | F63: At least one unread notification; badges enabled. | G63: 1. Open the inbox. 2. Tap an unread row. 3. Close the detail sheet and return Home. | H63: A detail sheet shows localised title, body, and time. The row becomes read. unreadCount and badgeCount decrease. Home orange badge updates. | I63: After read the notifications, the unread Count and badgeCount dcrease. | J63: Pass
...

Sheet Test Report
A1: KitchMemo Test Report
A2: Fill the Status column on Test Cases. Totals on this sheet update automatically.
A4: 1. Document information
A5: Product | C5: KitchMemo
A6: Version | C6: 1.0.0 (Expo app + Express API + Supabase)
A7: Test round | C7: Functional test of currently implemented MVP features
A8: Test date | C8: 2026-09-03
A9: Tester(s)
A10: Environment | C10: Physical Android/iOS device or Expo Go; Express on LAN; development Supabase project
A11: Build notes | C11: Chinese is the default UI language. English is switched from Me > Language. Recipes stay paused. Profile/Me is in the tab bar; Wins/achievements is still hidden.
A12: In scope | C12: Onboarding, home 3D kitchen, freshness prompt, fridge inventory, add/manual/photo/AI preset, item detail, shopping checkout of checked items, in-app notifications, shared inventory events, device profile nickname, notification preferences, local expiry/inactivity reminders, Expo push to other members, sharing, device recovery, i18n, sync.
A13: Out of scope | C13: Achievements API, category management API, explicit discard action, recipe discovery as a destination, Expo push receipt polling, user-uploaded avatars, persisted taste/diet preferences.
A15: 2. Execution summary
A16: Metric | B16: Count | C16: Notes
A17: Total cases | B17: =COUNTA('Test Cases'!A2:A100) -> 99 | C17: All designed cases in this workbook
A18: Executed | B18: =COUNTIF('Test Cases'!$J$2:$J$100,"Pass")+COUNTIF('Test Cases'!$J$2:$J$100,"Fail") -> 73 | C18: Pass + Fail
A19: Pass | B19: =COUNTIF('Test Cases'!$J$2:$J$100,"Pass") -> 71 | C19: Behaviour matches expected result
A20: Fail | B20: =COUNTIF('Test Cases'!$J$2:$J$100,"Fail") -> 2 | C20: Defect confirmed
A21: Blocked | B21: =COUNTIF('Test Cases'!$J$2:$J$100,"Blocked") -> 25 | C21: Cannot run due to environment or dependency
A22: Not executed | B22: =COUNTIF('Test Cases'!$J$2:$J$100,"Not executed")+COUNTBLANK('Test Cases'!$J$2:$J$100) -> 1 | C22: Blank status counts as not executed
A23: N/A | B23: =COUNTIF('Test Cases'!$J$2:$J$100,"N/A") -> 0 | C23: Not applicable in this environment
A24: Pass rate | B24: =IF(B18=0,"N/A",B19/B18) -> 0.97260274 | C24: Pass / Executed
A26: 3. Coverage by module
A27: Module | B27: Total | C27: Pass | D27: Fail | E27: Blocked | F27: Not executed
A28: Add item | B28: =COUNTIF('Test Cases'!B:B,A28) -> 5 | C28: =COUNTIFS('Test Cases'!B:B,A28,'Test Cases'!J:J,"Pass") -> 5 | D28: =COUNTIFS('Test Cases'!B:B,A28,'Test Cases'!J:J,"Fail") -> 0 | E28: =COUNTIFS('Test Cases'!B:B,A28,'Test Cases'!J:J,"Blocked") -> 0 | F28: =COUNTIFS('Test Cases'!B:B,A28,'Test Cases'!J:J,"Not executed")+COUNTIFS('Test Cases'!B:B,A28,'Test Cases'!J:J,"") -> 0
A29: Device recovery | B29: =COUNTIF('Test Cases'!B:B,A29) -> 3 | C29: =COUNTIFS('Test Cases'!B:B,A29,'Test Cases'!J:J,"Pass") -> 0 | D29: =COUNTIFS('Test Cases'!B:B,A29,'Test Cases'!J:J,"Fail") -> 0 | E29: =COUNTIFS('Test Cases'!B:B,A29,'Test Cases'!J:J,"Blocked") -> 3 | F29: =COUNTIFS('Test Cases'!B:B,A29,'Test Cases'!J:J,"Not executed")+COUNTIFS('Test Cases'!B:B,A29,'Test Cases'!J:J,"") -> 0
A30: Fridge | B30: =COUNTIF('Test Cases'!B:B,A30) -> 10 | C30: =COUNTIFS('Test Cases'!B:B,A30,'Test Cases'!J:J,"Pass") -> 10 | D30: =COUNTIFS('Test Cases'!B:B,A30,'Test Cases'!J:J,"Fail") -> 0 | E30: =COUNTIFS('Test Cases'!B:B,A30,'Test Cases'!J:J,"Blocked") -> 0 | F30: =COUNTIFS('Test Cases'!B:B,A30,'Test Cases'!J:J,"Not executed")+COUNTIFS('Test Cases'!B:B,A30,'Test Cases'!J:J,"") -> 0
A31: Home | B31: =COUNTIF('Test Cases'!B:B,A31) -> 13 | C31: =COUNTIFS('Test Cases'!B:B,A31,'Test Cases'!J:J,"Pass") -> 13 | D31: =COUNTIFS('Test Cases'!B:B,A31,'Test Cases'!J:J,"Fail") -> 0 | E31: =COUNTIFS('Test Cases'!B:B,A31,'Test Cases'!J:J,"Blocked") -> 0 | F31: =COUNTIFS('Test Cases'!B:B,A31,'Test Cases'!J:J,"Not executed")+COUNTIFS('Test Cases'!B:B,A31,'Test Cases'!J:J,"") -> 0
A32: Inventory detail | B32: =COUNTIF('Test Cases'!B:B,A32) -> 5 | C32: =COUNTIFS('Test Cases'!B:B,A32,'Test Cases'!J:J,"Pass") -> 5 | D32: =COUNTIFS('Test Cases'!B:B,A32,'Test Cases'!J:J,"Fail") -> 0 | E32: =COUNTIFS('Test Cases'!B:B,A32,'Test Cases'!J:J,"Blocked") -> 0 | F32: =COUNTIFS('Test Cases'!B:B,A32,'Test Cases'!J:J,"Not executed")+COUNTIFS('Test Cases'!B:B,A32,'Test Cases'!J:J,"") -> 0
A33: Inventory entry | B33: =COUNTIF('Test Cases'!B:B,A33) -> 8 | C33: =COUNTIFS('Test Cases'!B:B,A33,'Test Cases'!J:J,"Pass") -> 8 | D33: =COUNTIFS('Test Cases'!B:B,A33,'Test Cases'!J:J,"Fail") -> 0 | E33: =COUNTIFS('Test Cases'!B:B,A33,'Test Cases'!J:J,"Blocked") -> 0 | F33: =COUNTIFS('Test Cases'!B:B,A33,'Test Cases'!J:J,"Not executed")+COUNTIFS('Test Cases'!B:B,A33,'Test Cases'!J:J,"") -> 0
A34: Language | B34: =COUNTIF('Test Cases'!B:B,A34) -> 2 | C34: =COUNTIFS('Test Cases'!B:B,A34,'Test Cases'!J:J,"Pass") -> 1 | D34: =COUNTIFS('Test Cases'!B:B,A34,'Test Cases'!J:J,"Fail") -> 1 | E34: =COUNTIFS('Test Cases'!B:B,A34,'Test Cases'!J:J,"Blocked") -> 0 | F34: =COUNTIFS('Test Cases'!B:B,A34,'Test Cases'!J:J,"Not executed")+COUNTIFS('Test Cases'!B:B,A34,'Test Cases'!J:J,"") -> 0
A35: Notification settings | B35: =COUNTIF('Test Cases'!B:B,A35) -> 5 | C35: =COUNTIFS('Test Cases'!B:B,A35,'Test Cases'!J:J,"Pass") -> 3 | D35: =COUNTIFS('Test Cases'!B:B,A35,'Test Cases'!J:J,"Fail") -> 0 | E35: =COUNTIFS('Test Cases'!B:B,A35,'Test Cases'!J:J,"Blocked") -> 2 | F35: =COUNTIFS('Test Cases'!B:B,A35,'Test Cases'!J:J,"Not executed")+COUNTIFS('Test Cases'!B:B,A35,'Test Cases'!J:J,"") -> 0
A36: Notifications | B36: =COUNTIF('Test Cases'!B:B,A36) -> 9 | C36: =COUNTIFS('Test Cases'!B:B,A36,'Test Cases'!J:J,"Pass") -> 5 | D36: =COUNTIFS('Test Cases'!B:B,A36,'Test Cases'!J:J,"Fail") -> 1 | E36: =COUNTIFS('Test Cases'!B:B,A36,'Test Cases'!J:J,"Blocked") -> 2 | F36: =COUNTIFS('Test Cases'!B:B,A36,'Test Cases'!J:J,"Not executed")+COUNTIFS('Test Cases'!B:B,A36,'Test Cases'!J:J,"") -> 1
A37: Onboarding | B37: =COUNTIF('Test Cases'!B:B,A37) -> 4 | C37: =COUNTIFS('Test Cases'!B:B,A37,'Test Cases'!J:J,"Pass") -> 4 | D37: =COUNTIFS('Test Cases'!B:B,A37,'Test Cases'!J:J,"Fail") -> 0 | E37: =COUNTIFS('Test Cases'!B:B,A37,'Test Cases'!J:J,"Blocked") -> 0 | F37: =COUNTIFS('Test Cases'!B:B,A37,'Test Cases'!J:J,"Not executed")+COUNTIFS('Test Cases'!B:B,A37,'Test Cases'!J:J,"") -> 0
A38: Photo recognition | B38: =COUNTIF('Test Cases'!B:B,A38) -> 4 | C38: =COUNTIFS('Test Cases'!B:B,A38,'Test Cases'!J:J,"Pass") -> 3 | D38: =COUNTIFS('Test Cases'!B:B,A38,'Test Cases'!J:J,"Fail") -> 0 | E38: =COUNTIFS('Test Cases'!B:B,A38,'Test Cases'!J:J,"Blocked") -> 1 | F38: =COUNTIFS('Test Cases'!B:B,A38,'Test Cases'!J:J,"Not executed")+COUNTIFS('Test Cases'!B:B,A38,'Test Cases'!J:J,"") -> 0
A39: Profile | B39: =COUNTIF('Test Cases'!B:B,A39) -> 6 | C39: =COUNTIFS('Test Cases'!B:B,A39,'Test Cases'!J:J,"Pass") -> 5 | D39: =COUNTIFS('Test Cases'!B:B,A39,'Test Cases'!J:J,"Fail") -> 0 | E39: =COUNTIFS('Test Cases'!B:B,A39,'Test Cases'!J:J,"Blocked") -> 1 | F39: =COUNTIFS('Test Cases'!B:B,A39,'Test Cases'!J:J,"Not executed")+COUNTIFS('Test Cases'!B:B,A39,'Test Cases'!J:J,"") -> 0
... A43: System reminders | B43: =COUNTIF('Test Cases'!B:B,A43) -> 4 | C43: =COUNTIFS('Test Cases'!B:B,A43,'Test Cases'!J:J,"Pass") -> 2 | D43: =COUNTIFS('Test Cases'!B:B,A43,'Test Cases'!J:J,"Fail") -> 0 | E43: =COUNTIFS('Test Cases'!B:B,A43,'Test Cases'!J:J,"Blocked") -> 2 | F43: =COUNTIFS('Test Cases'!B:B,A43,'Test Cases'!J:J,"Not executed")+COUNTIFS('Test Cases'!B:B,A43,'Test Cases'!J:J,"") -> 0
A45: 4. Result distribution (chart data)
A46: Result | B46: Count
A47: Pass | B47: =B19 -> 71
...
